[2024-03-11T03:39:43.584+0000] {taskinstance.py:1125} INFO - Dependencies all met for dep_context=non-requeueable deps ti=<TaskInstance: clear_database_content.clear_database_content_task manual__2024-03-11T03:39:42.342044+00:00 [queued]>
[2024-03-11T03:39:43.596+0000] {taskinstance.py:1125} INFO - Dependencies all met for dep_context=requeueable deps ti=<TaskInstance: clear_database_content.clear_database_content_task manual__2024-03-11T03:39:42.342044+00:00 [queued]>
[2024-03-11T03:39:43.596+0000] {taskinstance.py:1331} INFO - Starting attempt 1 of 1
[2024-03-11T03:39:43.612+0000] {taskinstance.py:1350} INFO - Executing <Task(MySqlOperator): clear_database_content_task> on 2024-03-11 03:39:42.342044+00:00
[2024-03-11T03:39:43.616+0000] {standard_task_runner.py:57} INFO - Started process 106 to run task
[2024-03-11T03:39:43.620+0000] {standard_task_runner.py:84} INFO - Running: ['***', 'tasks', 'run', 'clear_database_content', 'clear_database_content_task', 'manual__2024-03-11T03:39:42.342044+00:00', '--job-id', '308', '--raw', '--subdir', 'DAGS_FOLDER/delete_data_dag.py', '--cfg-path', '/tmp/tmphn30om74']
[2024-03-11T03:39:43.621+0000] {standard_task_runner.py:85} INFO - Job 308: Subtask clear_database_content_task
[2024-03-11T03:39:43.687+0000] {task_command.py:410} INFO - Running <TaskInstance: clear_database_content.clear_database_content_task manual__2024-03-11T03:39:42.342044+00:00 [running]> on host c8342f43fbfc
[2024-03-11T03:39:43.780+0000] {taskinstance.py:1570} INFO - Exporting env vars: AIRFLOW_CTX_DAG_OWNER='***' AIRFLOW_CTX_DAG_ID='clear_database_content' AIRFLOW_CTX_TASK_ID='clear_database_content_task' AIRFLOW_CTX_EXECUTION_DATE='2024-03-11T03:39:42.342044+00:00' AIRFLOW_CTX_TRY_NUMBER='1' AIRFLOW_CTX_DAG_RUN_ID='manual__2024-03-11T03:39:42.342044+00:00'
[2024-03-11T03:39:43.781+0000] {sql.py:262} INFO - Executing: DELETE FROM penguins_data
[2024-03-11T03:39:43.800+0000] {taskinstance.py:1847} ERROR - Task failed with exception
Traceback (most recent call last):
  File "/home/airflow/.local/lib/python3.7/site-packages/airflow/providers/common/sql/operators/sql.py", line 263, in execute
    hook = self.get_db_hook()
  File "/home/airflow/.local/lib/python3.7/site-packages/airflow/providers/common/sql/operators/sql.py", line 181, in get_db_hook
    return self._hook
  File "/home/airflow/.local/lib/python3.7/site-packages/cached_property.py", line 36, in __get__
    value = obj.__dict__[self.func.__name__] = self.func(obj)
  File "/home/airflow/.local/lib/python3.7/site-packages/airflow/providers/common/sql/operators/sql.py", line 143, in _hook
    conn = BaseHook.get_connection(self.conn_id)
  File "/home/airflow/.local/lib/python3.7/site-packages/airflow/hooks/base.py", line 72, in get_connection
    conn = Connection.get_connection_from_secrets(conn_id)
  File "/home/airflow/.local/lib/python3.7/site-packages/airflow/models/connection.py", line 434, in get_connection_from_secrets
    raise AirflowNotFoundException(f"The conn_id `{conn_id}` isn't defined")
airflow.exceptions.AirflowNotFoundException: The conn_id `mysql_conn` isn't defined
[2024-03-11T03:39:43.805+0000] {taskinstance.py:1373} INFO - Marking task as FAILED. dag_id=clear_database_content, task_id=clear_database_content_task, execution_date=20240311T033942, start_date=20240311T033943, end_date=20240311T033943
[2024-03-11T03:39:43.818+0000] {standard_task_runner.py:109} ERROR - Failed to execute job 308 for task clear_database_content_task (The conn_id `mysql_conn` isn't defined; 106)
[2024-03-11T03:39:43.841+0000] {local_task_job_runner.py:232} INFO - Task exited with return code 1
[2024-03-11T03:39:43.862+0000] {taskinstance.py:2674} INFO - 0 downstream tasks scheduled from follow-on schedule check
