[2024-03-11T03:46:32.358+0000] {taskinstance.py:1125} INFO - Dependencies all met for dep_context=non-requeueable deps ti=<TaskInstance: clear_database_content.clear_database_task scheduled__2024-03-10T00:00:00+00:00 [queued]>
[2024-03-11T03:46:32.371+0000] {taskinstance.py:1125} INFO - Dependencies all met for dep_context=requeueable deps ti=<TaskInstance: clear_database_content.clear_database_task scheduled__2024-03-10T00:00:00+00:00 [queued]>
[2024-03-11T03:46:32.372+0000] {taskinstance.py:1331} INFO - Starting attempt 1 of 1
[2024-03-11T03:46:32.388+0000] {taskinstance.py:1350} INFO - Executing <Task(PythonOperator): clear_database_task> on 2024-03-10 00:00:00+00:00
[2024-03-11T03:46:32.393+0000] {standard_task_runner.py:57} INFO - Started process 56 to run task
[2024-03-11T03:46:32.397+0000] {standard_task_runner.py:84} INFO - Running: ['***', 'tasks', 'run', 'clear_database_content', 'clear_database_task', 'scheduled__2024-03-10T00:00:00+00:00', '--job-id', '311', '--raw', '--subdir', 'DAGS_FOLDER/delete_data_dag.py', '--cfg-path', '/tmp/tmpr71tx7s6']
[2024-03-11T03:46:32.399+0000] {standard_task_runner.py:85} INFO - Job 311: Subtask clear_database_task
[2024-03-11T03:46:32.459+0000] {task_command.py:410} INFO - Running <TaskInstance: clear_database_content.clear_database_task scheduled__2024-03-10T00:00:00+00:00 [running]> on host c8342f43fbfc
[2024-03-11T03:46:32.550+0000] {taskinstance.py:1570} INFO - Exporting env vars: AIRFLOW_CTX_DAG_OWNER='***' AIRFLOW_CTX_DAG_ID='clear_database_content' AIRFLOW_CTX_TASK_ID='clear_database_task' AIRFLOW_CTX_EXECUTION_DATE='2024-03-10T00:00:00+00:00' AIRFLOW_CTX_TRY_NUMBER='1' AIRFLOW_CTX_DAG_RUN_ID='scheduled__2024-03-10T00:00:00+00:00'
[2024-03-11T03:46:32.559+0000] {taskinstance.py:1847} ERROR - Task failed with exception
Traceback (most recent call last):
  File "/home/airflow/.local/lib/python3.7/site-packages/sqlalchemy/engine/base.py", line 1800, in _execute_context
    cursor, statement, parameters, context
  File "/home/airflow/.local/lib/python3.7/site-packages/sqlalchemy/engine/default.py", line 717, in do_execute
    cursor.execute(statement, parameters)
psycopg2.errors.UndefinedTable: relation "penguins_data" does not exist
LINE 1: DELETE FROM penguins_data
                    ^


The above exception was the direct cause of the following exception:

Traceback (most recent call last):
  File "/home/airflow/.local/lib/python3.7/site-packages/airflow/operators/python.py", line 181, in execute
    return_value = self.execute_callable()
  File "/home/airflow/.local/lib/python3.7/site-packages/airflow/operators/python.py", line 198, in execute_callable
    return self.python_callable(*self.op_args, **self.op_kwargs)
  File "/opt/airflow/dags/delete_data_dag.py", line 12, in clear_database_content
    conn.execute('DELETE FROM penguins_data')
  File "/home/airflow/.local/lib/python3.7/site-packages/sqlalchemy/engine/base.py", line 1276, in execute
    future=False,
  File "/home/airflow/.local/lib/python3.7/site-packages/sqlalchemy/engine/base.py", line 1582, in _exec_driver_sql
    distilled_parameters,
  File "/home/airflow/.local/lib/python3.7/site-packages/sqlalchemy/engine/base.py", line 1843, in _execute_context
    e, statement, parameters, cursor, context
  File "/home/airflow/.local/lib/python3.7/site-packages/sqlalchemy/engine/base.py", line 2024, in _handle_dbapi_exception
    sqlalchemy_exception, with_traceback=exc_info[2], from_=e
  File "/home/airflow/.local/lib/python3.7/site-packages/sqlalchemy/util/compat.py", line 207, in raise_
    raise exception
  File "/home/airflow/.local/lib/python3.7/site-packages/sqlalchemy/engine/base.py", line 1800, in _execute_context
    cursor, statement, parameters, context
  File "/home/airflow/.local/lib/python3.7/site-packages/sqlalchemy/engine/default.py", line 717, in do_execute
    cursor.execute(statement, parameters)
sqlalchemy.exc.ProgrammingError: (psycopg2.errors.UndefinedTable) relation "penguins_data" does not exist
LINE 1: DELETE FROM penguins_data
                    ^

[SQL: DELETE FROM penguins_data]
(Background on this error at: https://sqlalche.me/e/14/f405)
[2024-03-11T03:46:32.580+0000] {taskinstance.py:1373} INFO - Marking task as FAILED. dag_id=clear_database_content, task_id=clear_database_task, execution_date=20240310T000000, start_date=20240311T034632, end_date=20240311T034632
[2024-03-11T03:46:32.600+0000] {standard_task_runner.py:109} ERROR - Failed to execute job 311 for task clear_database_task ((psycopg2.errors.UndefinedTable) relation "penguins_data" does not exist
LINE 1: DELETE FROM penguins_data
                    ^

[SQL: DELETE FROM penguins_data]
(Background on this error at: https://sqlalche.me/e/14/f405); 56)
[2024-03-11T03:46:32.616+0000] {local_task_job_runner.py:232} INFO - Task exited with return code 1
[2024-03-11T03:46:32.639+0000] {taskinstance.py:2674} INFO - 0 downstream tasks scheduled from follow-on schedule check
